Workbook
Name aaaaaaa: #REF!
Name aaaaaaa: #REF!
Name aaaaaaa: #REF!
Name Actual_Number_of_Payments: IFERROR(IF(LoanIsGood,IF(PaymentsPerYear=1,1,MATCH(0.01,End_Bal,-1)+1)),"")
Name ActualNumberOfPayments: IFERROR(IF('Breakeven- avg GP (2)'!LoanIsGood,IF('Breakeven- avg GP (2)'!PaymentsPerYear=1,1,MATCH(0.01,'Breakeven- avg GP (2)'!End_Bal,-1)+1)),"")
Name ActualNumberOfPayments: IFERROR(IF('Breakeven- avg GP (3)'!LoanIsGood,IF('Breakeven- avg GP (3)'!PaymentsPerYear=1,1,MATCH(0.01,'Breakeven- avg GP (3)'!End_Bal,-1)+1)),"")
Name ActualNumberOfPayments: IFERROR(IF(LoanIsGood,IF(PaymentsPerYear=1,1,MATCH(0.01,End_Bal,-1)+1)),"")
Name ActualNumberOfPayments: IFERROR(IF([0]!LoanIsGood,IF([0]!PaymentsPerYear=1,1,MATCH(0.01,[0]!End_Bal,-1)+1)),"")
Name ActualNumberOfPayments: IFERROR(IF(LoanIsGood,IF(PaymentsPerYear=1,1,MATCH(0.01,End_Bal,-1)+1)),"")
Name ActualNumberOfPayments: IFERROR(IF(LoanIsGood,IF(PaymentsPerYear=1,1,MATCH(0.01,End_Bal,-1)+1)),"")
Name ads: #REF!
Name ads: #REF!
Name ads: #REF!
Name as: #REF!
Name as: #REF!
Name as: #REF!
Name asd: #REF!
Name asd: #REF!
Name asd: #REF!
Name asf: #REF!
Name bank_cy: #REF!
Name bank_cy: #REF!
Name bank_cy: #REF!
Name Beg_Bal: #REF!
Name Beg_Bal: #REF!
Name Beg_Bal: #REF!
Name bng: #REF!
Name bng: #REF!
Name bng: #REF!
Name Ccc: #REF!
Name Ccc: #REF!
Name Ccc: #REF!
Name ColumnTitle1: #REF!
Name ColumnTitle1: #REF!
Name ColumnTitle1: #REF!
Name creditors: #REF!
Name creditors_cy: #REF!
Name creditors_cy: #REF!
Name creditors_cy: #REF!
Name Cum_Int: #REF!
Name Cum_Int: #REF!
Name Cum_Int: #REF!
Name Data: #REF!
Name Data: #REF!
Name Data: #REF!
Name End_Bal: #REF!
Name End_Bal: #REF!
Name End_Bal: #REF!
Name expense_cy: #REF!
Name expense_cy: #REF!
Name expense_cy: #REF!
Name export: #REF!
Name export: #REF!
Name export: #REF!
Name export_cy: #REF!
Name export_cy: #REF!
Name export_cy: #REF!
Name Extra_Pay: #REF!
Name Extra_Pay: #REF!
Name Extra_Pay: #REF!

Sheet Incentive Calc
B2: Sales Achievement | C2: 50%-59 | D2: 60%-69 | E2: 70%-79 | F2: 80%-89 | G2: 90%-99 | H2: 100%-109 | I2: 110%-119 | J2: 120%+
B3: Incentive multiplier | C3: 0.005 | D3: 0.0075 | E3: 0.01 | F3: 0.0125 | G3: 0.015 | H3: 0.05 | I3: 0.06 | J3: 0.07
A7: Days | C7: Month | D7: Actual Sales monthly | E7: Target monthly | F7: Target achieved in % | G7: Prev Incentive | H7: Target | I7: Target Achieved | J7: New 5% NP | K7: Per Person incentive.
A8: 31 | B8: Banani | C8: Jan | D8: 811487 | E8: =31000*31 -> 961000 | F8: =D8/E8*100 -> 84.441935 | G8: 7100 | H8: =31000*31 -> 961000 | I8: =D8/H8*100 -> 84.441935 | J8: =D8*F3 -> 10143.588
A9: 28 | C9: Feb | D9: 689034 | E9: =31000*28 -> 868000 | F9: =D9/E9*100 -> 79.381797 | G9: 7800 | H9: =31000*28 -> 868000 | I9: =D9/H9*100 -> 79.381797 | J9: =D9*E3 -> 6890.34
A10: 31 | C10: Mar | D10: 836699 | E10: =31000*31 -> 961000 | F10: =D10/E10*100 -> 87.065453 | G10: 11800 | H10: =31000*31 -> 961000 | I10: =D10/H10*100 -> 87.065453 | J10: =D10*F3 -> 10458.738
A11: 30 | C11: Apr | D11: 714728 | E11: =31000*30 -> 930000 | F11: =D11/E11*100 -> 76.852473 | G11: =2500+1800 -> 4300 | H11: =31000*30 -> 930000 | I11: =D11/H11*100 -> 76.852473 | J11: =D11*E3 -> 7147.28
B12: Totals | D12: =SUM(D8:D11) -> 3051948 | E12: =SUM(E8:E11) -> 3720000 | F12: =SUM(F8:F11) -> 327.74166 | G12: =SUM(G8:G11) -> 31000 | J12: =SUM(J8:J11) -> 34639.945 | K12: =J12/'Breakeven- avg GP (3)'!D38 -> 5773.3242
C15: Month | D15: Actual Sales monthly | E15: Target monthly | F15: Target achieved in % | G15: Prev Incentive | H15: Target | I15: Target Achieved | J15: New 5% NP | K15: Per Person incentive.
B16: Lalmatia | C16: Jan | D16: 556246 | E16: =33000*31 -> 1023000 | F16: =D16/E16*100 -> 54.373998 | G16: 800 | H16: =33000*31 -> 1023000 | I16: =D16/H16*100 -> 54.373998 | J16: =D16*C3 -> 2781.23
C17: Feb | D17: 581480 | E17: =33000*28 -> 924000 | F17: =D17/E17*100 -> 62.930736 | G17: 1800 | H17: =33000*28 -> 924000 | I17: =D17/H17*100 -> 62.930736 | J17: =D17*D3 -> 4361.1
C18: Mar | D18: 619527 | E18: =33000*31 -> 1023000 | F18: =D18/E18*100 -> 60.559824 | G18: 1600 | H18: =33000*31 -> 1023000 | I18: =D18/H18*100 -> 60.559824 | J18: =D18*D3 -> 4646.4525
C19: Apr | D19: 711082 | E19: =33000*30 -> 990000 | F19: =D19/E19*100 -> 71.826465 | G19: 3000 | H19: =33000*30 -> 990000 | I19: =D19/H19*100 -> 71.826465 | J19: =D19*E3 -> 7110.82
B20: Totals | D20: =SUM(D16:D19) -> 2468335 | E20: =SUM(E17:E19) -> 2937000 | F20: =SUM(F17:F19) -> 195.31702 | G20: =SUM(G17:G19) -> 6400 | J20: =SUM(J17:J19) -> 16118.372 | K20: =J20/'Breakeven- avg GP (3)'!F38 -> 2686.3954
A22: H | C22: Month | D22: Actual Sales monthly | E22: Target monthly | F22: Target achieved in % | G22: Prev Incentive | H22: Target | I22: Target Achieved | J22: New 5% NP | K22: Per Person incentive.
B23: Asian Tower | C23: Jan | D23: 1049100 | E23: =61000*31 -> 1891000 | F23: =D23/E23*100 -> 55.478583 | G23: 1000 | H23: =61000*31 -> 1891000 | I23: =D23/H23*100 -> 55.478583 | J23: =D23*C3 -> 5245.5
C24: Feb | D24: 930796 | E24: =61000*28 -> 1708000 | F24: =D24/E24*100 -> 54.496253 | H24: =61000*28 -> 1708000 | I24: =D24/H24*100 -> 54.496253 | J24: =D24*C3 -> 4653.98
C25: Mar | D25: 892677 | E25: =61000*31 -> 1891000 | F25: =D25/E25*100 -> 47.20661 | H25: =61000*31 -> 1891000 | I25: =D25/H25*100 -> 47.20661 | J25: =D25*C5 -> 0
C26: Apr | D26: 1735659 | E26: =61000*30 -> 1830000 | F26: =D26/E26*100 -> 94.844754 | G26: 13000 | H26: =61000*30 -> 1830000 | I26: =D26/H26*100 -> 94.844754 | J26: =D26*G3 -> 26034.885
B27: Totals | D27: =SUM(D23:D26) -> 4608232 | E27: =SUM(E24:E26) -> 5429000 | F27: =SUM(F24:F26) -> 196.54762 | G27: =SUM(G24:G26) -> 13000 | J27: =SUM(J24:J26) -> 30688.865 | K27: =J27/'Breakeven- avg GP (3)'!E38 -> 3836.1081
C29: Month | D29: Actual Sales monthly | E29: Target monthly | F29: Target achieved in % | G29: Prev Incentive | H29: Target | I29: Target Achieved | J29: New 5% NP | K29: Per Person incentive.
B30: Fakirapool | C30: Jan | D30: 194544 | E30: =27000*31 -> 837000 | F30: =D30/E30*100 -> 23.243011 | H30: =27000*31 -> 837000 | I30: =D30/H30*100 -> 23.243011
C31: Feb | D31: 240130 | E31: =27000*28 -> 756000 | F31: =D31/E31*100 -> 31.763228 | H31: =27000*28 -> 756000 | I31: =D31/H31*100 -> 31.763228
C32: Mar | D32: 282406 | E32: =27000*31 -> 837000 | F32: =D32/E32*100 -> 33.740263 | G32: 500 | H32: =27000*31 -> 837000 | I32: =D32/H32*100 -> 33.740263
C33: Apr | D33: 363565 | E33: =27000*30 -> 810000 | F33: =D33/E33*100 -> 44.884568 | H33: =27000*30 -> 810000 | I33: =D33/H33*100 -> 44.884568
B34: Totals | D34: =SUM(D30:D33) -> 1080645 | E34: =SUM(E30:E33) -> 3240000 | F34: =SUM(F31:F33) -> 110.38806 | G34: =SUM(G30:G33) -> 500 | J34: =SUM(J30:J33) -> 0
C36: Month | D36: Actual Sales monthly | E36: Target monthly | F36: Target achieved in % | G36: Prev Incentive | H36: Target | I36: Target Achieved | J36: New 5% NP | K36: Per Person incentive.
B37: Banani DOHS | C37: Jan | D37: 0 | E37: 0
C38: Feb | D38: 0 | E38: 0
C39: Mar | D39: 313181 | E39: =30000*16 -> 480000 | F39: =D39/E39*100 -> 65.246042 | G39: 2600 | H39: =30000*16 -> 480000 | I39: =D39/H39*100 -> 65.246042 | J39: =D39*D3 -> 2348.8575
C40: Apr | D40: 853171 | E40: =30000*30 -> 900000 | F40: =D40/E40*100 -> 94.796778 | G40: =4500+4900 -> 9400 | H40: =30000*30 -> 900000 | I40: =D40/H40*100 -> 94.796778 | J40: =D40*G3 -> 12797.565
B41: Totals | D41: =SUM(D37:D40) -> 1166352 | E41: =SUM(E37:E40) -> 1380000 | G41: =SUM(G37:G40) -> 12000 | J41: =SUM(J37:J40) -> 15146.422 | K41: =J41/'Breakeven- avg GP (3)'!M38 -> 2524.4037
C43: Month | D43: Actual Sales monthly | E43: Target monthly | F43: Target achieved in % | G43: Prev Incentive | H43: Target | I43: Target Achieved | J43: New 5% NP | K43: Per Person incentive.
B44: Kazipara | C44: Jan | D44: 0 | E44: 0
C45: Feb | D45: 0 | E45: 0
C46: Mar | D46: 321609 | E46: =35000*25 -> 875000 | F46: =D46/E46*100 -> 36.755314 | H46: =35000*25 -> 875000 | I46: =D46/H46*100 -> 36.755314
C47: Apr | D47: 616015 | E47: =35000*30 -> 1050000 | F47: =D47/E47*100 -> 58.668095 | G47: 800 | H47: =35000*30 -> 1050000 | I47: =D47/H47*100 -> 58.668095 | J47: =D47*C3 -> 3080.075
B48: Totals | D48: =SUM(D44:D47) -> 937624 | E48: =SUM(E44:E47) -> 1925000 | G48: =SUM(G44:G47) -> 800 | J48: =SUM(J44:J47) -> 3080.075 | K48: =J48/'Breakeven- avg GP (3)'!K38 -> 513.34583
C50: Month | D50: Actual Sales monthly | E50: Target monthly | F50: Target achieved in % | G50: Prev Incentive | H50: Target | I50: Target Achieved | J50: New 5% NP | K50: Per Person incentive.
B51: Mirpur 06 | C51: Jan | D51: 0 | E51: 0
...

Sheet Breakeven- avg GP (3)
B1: Particulars | D1: Banani | E1: Nikunja (Asian Tower) | F1: Lalmatia | G1: Nurjahan Road | H1: Benaroshi Polli | I1: Fakirapul | J1: Mirpur DOHS | K1: Kazipara | L1: Mirpur-6 | M1: Banani DOHS | N1: Nikunja 01 | O1: Zakir Hossain Road
B2: Average monthly sale( based on last 6 month)
B3: Average daily sale( based on last 6 month)
B5: Break even Sales per Month | D5: =D22/(28)*100 -> 765466.17 | E5: =E22/(28)*100 -> 1445801.6 | F5: =F22/(28)*100 -> 1138966.2 | G5: =G22/(28)*100 -> 1082041.2 | H5: =H22/(28)*100 -> 1149819.7 | I5: =I22/(28)*100 -> 917530.46 | J5: =J22/(28)*100 -> 585265.23 | K5: =K22/(28)*100 -> 887609.03 | ... O5: =O22/(28)*100 -> 795228.08
B7: Gross Profit | D7: =D5*D9 -> 214330.53 | E7: =E5*E9 -> 404824.46 | F7: =F5*F9 -> 318910.53 | G7: =G5*G9 -> 302971.53 | H7: =H5*H9 -> 321949.53 | I7: =I5*I9 -> 256908.53 | J7: =J5*J9 -> 163874.26 | K7: =K5*K9 -> 248530.53 | ... O7: =O5*O9 -> 222663.86
B9: Considering Average GP % | D9: 0.28 | E9: 0.28 | F9: 0.28 | G9: 0.28 | H9: 0.28 | I9: 0.28 | J9: 0.28 | K9: 0.28 | L9: 0.28 | M9: 0.28 | N9: 0.28 | O9: 0.28
B11: Proposed Cost per Month
B12: Rent | D12: 40000 | E12: 138600 | F12: 105264 | G12: 75000 | H12: 115000 | I12: 65000 | J12: 35000 | K12: 60000 | L12: 45000 | M12: 60000 | N12: 35000 | O12: 40000
B13: Service Charge | D13: 0 | E13: 20000 | F13: 0 | G13: 0 | H13: 0 | I13: 0 | J13: 0 | K13: 0 | L13: 0 | M13: 0 | O13: 0
B14: Electricity | D14: 38000 | E14: 60000 | F14: 40000 | G14: 60000 | H14: 50000 | I14: 40000 | J14: 35000 | K14: 40000 | L14: 35000 | M14: 20000 | N14: 25000 | O14: 30000
B15: Wasa | D15: 0 | E15: 0 | F15: 3000 | G15: 0 | H15: 0 | I15: 2000 | J15: 0 | K15: 3700 | L15: 1100 | M15: 2000 | N15: 0 | O15: 2000
B16: AIT On Rent | D16: 0 | E16: 0 | F16: =F12*0.1 -> 10526.4 | G16: 0 | H16: 0 | I16: 0 | J16: 0 | K16: 3000 | L16: 0 | M16: 6000 | N16: 0 | O16: 0
B17: Vat on Rent | D17: 0 | E17: 9000 | F17: =F12*0.15 -> 15789.6 | G17: =G12*0.15 -> 11250 | H17: =25000*0.15 -> 3750 | I17: =30000*0.15 -> 4500 | J17: =J12*0.15 -> 5250 | K17: =30000*0.15 -> 4500 | L17: =L12*0.15 -> 6750 | M17: 0 | N17: =N12*0.15 -> 5250 | O17: =O12*0.15 -> 6000
B18: Salary & Allowances | D18: =D36*D42+D37*D43 -> 131330.53 | E18: =E36*D42+E37*D43 -> 169224.46 | F18: =F36*D42+F37*D43 -> 131330.53 | G18: =G36*D42+G37*D43 -> 131330.53 | H18: =H36*D42+H37*D43 -> 131330.53 | I18: =I36*D42+I37*D43 -> 131330.53 | J18: =J36*D42+J37*D43+(5400+3600*2) -> 78265.264 | K18: =K36*D42+K37*D43 -> 131330.53 | L18: =L36*D42+L37*D43 -> 84612.23 | M18: =M36*D42+M37*D43 -> 131330.53 | N18: =N36*D42+N37*D43+(5400+3600*2) -> 78265.264 | O18: =D42*2+D43*4 -> 131330.53
B19: Maintenance | D19: 5000 | E19: 8000 | F19: 6000 | G19: 8000 | H19: 8000 | I19: 5000 | J19: 5000 | K19: 6000 | L19: 5000 | M19: 5000 | N19: 5000 | O19: 5000
B20: Cost of Fund | F20: 7000 | G20: 17391 | H20: 13869 | I20: 9078 | J20: 5359 | K20: 0 | L20: 7131 | M20: 4375 | N20: 5381 | O20: =(1000000*0.1*3)/36 -> 8333.3333
B21: Depreciation (not considered) | D21: 0 | E21: 0
B22: Total Proposed Cost | D22: =SUM(D12:D21) -> 214330.53 | E22: =SUM(E12:E21) -> 404824.46 | F22: =SUM(F12:F21) -> 318910.53 | G22: =SUM(G12:G21) -> 302971.53 | H22: =SUM(H12:H21) -> 321949.53 | I22: =SUM(I12:I21) -> 256908.53 | J22: =SUM(J12:J21) -> 163874.26 | K22: =SUM(K12:K21) -> 248530.53 | ... N22: =SUM(N12:N21) -> 153896.26 | O22: =SUM(O12:O20) -> 222663.86
B24: Profit/ (Loss) | D24: =D7-D22 -> 0 | E24: =E7-E22 -> 0 | F24: =F7-F22 -> 0 | G24: =G7-G22 -> 0 | H24: =H7-H22 -> 0 | I24: =I7-I22 -> 0 | J24: =J7-J22 -> 0 | K24: =K7-K22 -> 0 | ... M24: =M7-M22 -> 0
B28: Break even Sales per Day | D28: =D5/30 -> 25515.539 | E28: =E5/30 -> 48193.388 | F28: =F5/30 -> 37965.539 | G28: =G5/30 -> 36068.039 | H28: =H5/30 -> 38327.325 | I28: =I5/30 -> 30584.349 | J28: =J5/30 -> 19508.841 | K28: =K5/30 -> 29586.968 | ... O28: =O5/30 -> 26507.603
B30: Present Sales target/day | D30: 31000 | E30: 61000 | F30: 33000 | G30: 40000 | H30: 44000 | I30: 27000 | J30: 0 | K30: 0 | L30: 0 | M30: 30000 | N30: 0
B32: Proposed Sales target/day | D32: 35000 | E32: 62000 | F32: 49000 | G32: 42000 | H32: 45000 | I32: 31000 | J32: 23000 | K32: 38000 | L32: 29000 | M32: 33000 | N32: 21000 | O32: 24000
B34: Shift | D34: 2 | E34: 2 | F34: 2 | G34: 2 | H34: 2 | I34: 2 | J34: 1 | K34: 2 | L34: 2 | M34: 2 | N34: 1 | O34: 2
B36: Incharge/Barista | D36: 2 | E36: 2 | F36: 2 | G36: 2 | H36: 2 | I36: 2 | J36: 1 | K36: 2 | L36: 1 | M36: 2 | N36: 1 | O36: 2
B37: Surver/Outlet Asstt | D37: 4 | E37: 6 | F37: 4 | G37: 4 | H37: 4 | I37: 4 | J37: 2 | K37: 4 | L37: 3 | M37: 4 | N37: 2 | O37: 4
D38: =SUM(D36:D37) -> 6 | E38: =SUM(E36:E37) -> 8 | F38: =SUM(F36:F37) -> 6 | G38: =SUM(G36:G37) -> 6 | H38: =SUM(H36:H37) -> 6 | I38: =SUM(I36:I37) -> 6 | J38: =SUM(J36:J37) -> 3 | K38: =SUM(K36:K37) -> 6 | ... O38: =SUM(O36:O37) -> 6
B41: Average Salary & Allowances:
B42: Incharge/Barista | D42: 27771.333
B43: Surver/Outlet Asstt | D43: 18946.966
B45: Required daily Sales
B47: Name of Outlet | D47: Average Cost | F47: Breakeven Sales/day (avg. GP-28%) | G47: Sales amount against Net Profit | I47: Sales Target / day
D48: Per Month | E48: Per Day | G48: 0.05 | H48: 0.1 | J48: monthly target considering 5% net profit | K48: monthly target considering 10% net profit
B49: Banani | D49: =M66 -> 214330.53 | E49: =D49/30 -> 7144.351 | F49: =E49/28*100 -> 25515.539 | G49: =E49/23*100 -> 31062.395 | H49: =E49/18*100 -> 39690.839 | I49: 31500 | J49: =D49/23% -> 931871.86 | K49: =D49/18% -> 1190725.2
B50: Nikunja (Asian Tower) | D50: =M67 -> 404824.46 | E50: =D50/30 -> 13494.149 | F50: =E50/28*100 -> 48193.388 | G50: =E50/23*100 -> 58670.212 | H50: =E50/18*100 -> 74967.493 | I50: 59000 | J50: =D50/23% -> 1760106.3 | K50: =D50/18% -> 2249024.8
B51: Lalmatia | D51: =M68 -> 318910.53 | E51: =D51/30 -> 10630.351 | F51: =E51/28*100 -> 37965.539 | G51: =E51/23*100 -> 46218.917 | H51: =E51/18*100 -> 59057.505 | I51: 46500 | J51: =D51/23% -> 1386567.5 | K51: =D51/18% -> 1771725.2
B52: Nurjahan Road | D52: =M69 -> 302971.53 | E52: =D52/30 -> 10099.051 | F52: =E52/28*100 -> 36068.039 | G52: =E52/23*100 -> 43908.917 | H52: =E52/18*100 -> 56105.839 | I52: 44000 | J52: =D52/23% -> 1317267.5 | K52: =D52/18% -> 1683175.2
B53: Benaroshi Polli | D53: =M70 -> 321949.53 | E53: =D53/30 -> 10731.651 | F53: =E53/28*100 -> 38327.325 | G53: =E53/23*100 -> 46659.352 | H53: =E53/18*100 -> 59620.283 | I53: 47000 | J53: =D53/23% -> 1399780.6 | K53: =D53/18% -> 1788608.5
B54: Fakirapul | D54: =M71 -> 256908.53 | E54: =D54/30 -> 8563.6176 | F54: =E54/28*100 -> 30584.349 | G54: =E54/23*100 -> 37233.12 | H54: =E54/18*100 -> 47575.653 | I54: 37500 | J54: =D54/23% -> 1116993.6 | K54: =D54/18% -> 1427269.6
B55: Mirpur DOHS | D55: =M72 -> 163874.26 | E55: =D55/30 -> 5462.4755 | F55: =E55/28*100 -> 19508.841 | G55: =E55/23*100 -> 23749.893 | H55: =E55/18*100 -> 30347.086 | I55: 24000 | J55: =D55/23% -> 712496.8 | K55: =D55/18% -> 910412.58
B56: Kazipara | D56: =M73 -> 248530.53 | E56: =D56/30 -> 8284.351 | F56: =E56/28*100 -> 29586.968 | G56: =E56/23*100 -> 36018.917 | H56: =E56/18*100 -> 46024.172 | I56: 36500 | J56: =D56/23% -> 1080567.5 | K56: =D56/18% -> 1380725.2
...

Sheet Last 6 Months sales 
M1: Target | N1: Target Achieved
A3: AFC Six months sales report
A5: From Date | B5: To Date | C5: Outlets Name | D5: 6 Months Sales | E5: Average monthly Sale | F5: Average Daily Sale | G5: Target | J5: % of target reached | O5: sales volume 50% of target reached | P5: 0.005 | Q5: 0.6 | R5: 0.0075 | V5: Months | W5: Day
A6: 45962 | B6: 46142 | C6: ='[1]Breakeven- avg GP'!D5 -> Banani | D6: 4338578.8 | E6: =D6/((B6-A6+1)/30) -> 719101.47 | F6: =D6/(B6-A6+1) -> 23970.049 | G6: ='Breakeven- avg GP (3)'!K49 -> 1190725.2 | J6: =(E6/G6)*100 -> 60.391893 | M6: =G6*0.5 -> 595362.58 | N6: =0.5%*M6 -> 2976.8129 | O6: =G6*$Q$5 -> 714435.1 | P6: =O6*$R$5 -> 5358.2632 | T6: =(B6-A6+1)/30 -> 6.0333333 | U6: =B6-A6+1 -> 181
A7: 45962 | B7: 46142 | C7: ='[1]Breakeven- avg GP'!E5 -> Nikunja (Asian Tower) | D7: 6205389.3 | E7: =D7/((B7-A7+1)/30) -> 1028517.6 | F7: =D7/(B7-A7+1) -> 34283.919 | G7: ='Breakeven- avg GP (3)'!K50 -> 2249024.8 | J7: =(E7/G7)*100 -> 45.731714 | M7: =G7*0.5 -> 1124512.4 | N7: =0.5%*M7 -> 5622.5619 | O7: =G7*$Q$5 -> 1349414.9 | P7: =O7*$R$5 -> 10120.611 | T7: =(B7-A7+1)/30 -> 6.0333333 | U7: =B7-A7+1 -> 181
A8: 45962 | B8: 46142 | C8: ='[1]Breakeven- avg GP'!F5 -> Lalmatia | D8: 3300320.4 | E8: =D8/((B8-A8+1)/30) -> 547014.43 | F8: =D8/(B8-A8+1) -> 18233.814 | G8: ='Breakeven- avg GP (3)'!K51 -> 1771725.2 | J8: =(E8/G8)*100 -> 30.874678 | M8: =G8*0.5 -> 885862.58 | N8: =0.5%*M8 -> 4429.3129 | O8: =G8*$Q$5 -> 1063035.1 | P8: =O8*$R$5 -> 7972.7632 | T8: =(B8-A8+1)/30 -> 6.0333333 | U8: =B8-A8+1 -> 181
A9: 45984 | B9: 46142 | C9: ='[1]Breakeven- avg GP'!G5 -> Nurjahan Road | D9: 1908903.2 | E9: =D9/((B9-A9+1)/30) -> 360170.42 | F9: =D9/(B9-A9+1) -> 12005.681 | G9: ='Breakeven- avg GP (3)'!K52 -> 1683175.2 | J9: =(E9/G9)*100 -> 21.398273 | M9: =G9*0.5 -> 841587.58 | N9: =0.5%*M9 -> 4207.9379 | O9: =G9*$Q$5 -> 1009905.1 | P9: =O9*$R$5 -> 7574.2882 | T9: =(B9-A9+1)/30 -> 5.3 | U9: =B9-A9+1 -> 159
A10: 46025 | B10: 46142 | C10: ='[1]Breakeven- avg GP'!H5 -> Benaroshi Polli | D10: 1400828 | E10: =D10/((B10-A10+1)/30) -> 356142.72 | F10: =D10/(B10-A10+1) -> 11871.424 | G10: ='Breakeven- avg GP (3)'!K53 -> 1788608.5 | J10: =(E10/G10)*100 -> 19.911721 | M10: =G10*0.5 -> 894304.25 | N10: =0.5%*M10 -> 4471.5212 | O10: =G10*$Q$5 -> 1073165.1 | P10: =O10*$R$5 -> 8048.7382 | T10: =(B10-A10+1)/30 -> 3.9333333 | U10: =B10-A10+1 -> 118
A11: 46005 | B11: 46142 | C11: ='[1]Breakeven- avg GP'!I5 -> Fakirapul | D11: 1169386.1 | E11: =D11/((B11-A11+1)/30) -> 254214.38 | F11: =D11/(B11-A11+1) -> 8473.8127 | G11: ='Breakeven- avg GP (3)'!K54 -> 1427269.6 | J11: =(E11/G11)*100 -> 17.811238 | M11: =G11*0.5 -> 713634.8 | N11: =0.5%*M11 -> 3568.174 | O11: =G11*$Q$5 -> 856361.76 | P11: =O11*$R$5 -> 6422.7132 | T11: =(B11-A11+1)/30 -> 4.6 | U11: =B11-A11+1 -> 138
A12: 46044 | B12: 46142 | C12: ='[1]Breakeven- avg GP'!J5 -> Mirpur DOHS | D12: 902166.98 | E12: =D12/((B12-A12+1)/30) -> 273383.93 | F12: =D12/(B12-A12+1) -> 9112.7978 | G12: ='Breakeven- avg GP (3)'!K55 -> 910412.58 | J12: =(E12/G12)*100 -> 30.028576 | M12: =G12*0.5 -> 455206.29 | N12: =0.5%*M12 -> 2276.0314 | O12: =G12*$Q$5 -> 546247.55 | P12: =O12*$R$5 -> 4096.8566 | T12: =(B12-A12+1)/30 -> 3.3 | U12: =B12-A12+1 -> 99
A13: 46088 | B13: 46142 | C13: ='[1]Breakeven- avg GP'!K5 -> Kazipara | D13: 951725.43 | E13: =D13/((B13-A13+1)/30) -> 519122.96 | F13: =D13/(B13-A13+1) -> 17304.099 | G13: ='Breakeven- avg GP (3)'!K56 -> 1380725.2 | J13: =(E13/G13)*100 -> 37.597849 | M13: =G13*0.5 -> 690362.58 | N13: =0.5%*M13 -> 3451.8129 | O13: =G13*$Q$5 -> 828435.1 | P13: =O13*$R$5 -> 6213.2632 | T13: =(B13-A13+1)/30 -> 1.8333333 | U13: =B13-A13+1 -> 55
A14: 46094 | B14: 46142 | C14: ='[1]Breakeven- avg GP'!L5 -> Mirpur-6 | D14: 585818.68 | E14: =D14/((B14-A14+1)/30) -> 358664.5 | F14: =D14/(B14-A14+1) -> 11955.483 | G14: ='Breakeven- avg GP (3)'!K57 -> 1025517.9 | J14: =(E14/G14)*100 -> 34.973986 | M14: =G14*0.5 -> 512758.97 | N14: =0.5%*M14 -> 2563.7949 | O14: =G14*$Q$5 -> 615310.77 | P14: =O14*$R$5 -> 4614.8307 | T14: =(B14-A14+1)/30 -> 1.6333333 | U14: =B14-A14+1 -> 49
A15: 46097 | B15: 46142 | C15: ='[1]Breakeven- avg GP'!M5 -> Banani DOHS | D15: 1181240.3 | E15: =D15/((B15-A15+1)/30) -> 770374.08 | F15: =D15/(B15-A15+1) -> 25679.136 | G15: ='Breakeven- avg GP (3)'!K58 -> 1270586.3 | J15: =(E15/G15)*100 -> 60.631387 | M15: =G15*0.5 -> 635293.14 | N15: =0.5%*M15 -> 3176.4657 | O15: =G15*$Q$5 -> 762351.76 | P15: =O15*$R$5 -> 5717.6382 | T15: =(B15-A15+1)/30 -> 1.5333333 | U15: =B15-A15+1 -> 46
A16: 46138 | B16: 46142 | C16: ='[1]Breakeven- avg GP'!N5 -> Nikunja 01 | D16: 42303.45 | E16: =D16/((B16-A16+1)/30) -> 253820.7 | F16: =D16/(B16-A16+1) -> 8460.69 | G16: ='Breakeven- avg GP (3)'!K59 -> 854979.25 | J16: =(E16/G16)*100 -> 29.687352 | M16: =G16*0.5 -> 427489.62 | N16: =0.5%*M16 -> 2137.4481 | O16: =G16*$Q$5 -> 512987.55 | P16: =O16*$R$5 -> 3847.4066 | T16: =(B16-A16+1)/30 -> 0.16666667 | U16: =B16-A16+1 -> 5
B20: Sales Achievement | C20: 50%-59 | D20: 60%-69 | E20: 70%-79 | F20: 80%-89 | G20: 90%-99 | H20: 100%-109 | I20: 110%-119 | J20: 120%+
B21: Incentive multiplier | C21: 0.005 | D21: 0.0075 | E21: 0.01 | F21: 0.0125 | G21: 0.015 | H21: 0.05 | I21: 0.06 | J21: 0.07
A25: Days | C25: Month | D25: Actual Sales monthly | E25: Target monthly | F25: Target achieved in % | G25: Prev Incentive | H25: Target | I25: Target Achieved | J25: New 5% NP
A26: 31 | B26: Banani | C26: Jan | D26: 811487 | E26: =31000*31 -> 961000 | F26: =D26/E26*100 -> 84.441935 | G26: 7100 | H26: =31000*31 -> 961000 | I26: =D26/H26*100 -> 84.441935 | J26: =D26*F21 -> 10143.588
A27: 28 | C27: Feb | D27: 689034 | E27: =31000*28 -> 868000 | F27: =D27/E27*100 -> 79.381797 | G27: 7800 | H27: =31000*28 -> 868000 | I27: =D27/H27*100 -> 79.381797 | J27: =D27*E21 -> 6890.34
A28: 31 | C28: Mar | D28: 836699 | E28: =31000*31 -> 961000 | F28: =D28/E28*100 -> 87.065453 | G28: 11800 | H28: =31000*31 -> 961000 | I28: =D28/H28*100 -> 87.065453 | J28: =D28*F21 -> 10458.738
A29: 30 | C29: Apr | D29: 714728 | E29: =31000*30 -> 930000 | F29: =D29/E29*100 -> 76.852473 | G29: =2500+1800 -> 4300 | H29: =31000*30 -> 930000 | I29: =D29/H29*100 -> 76.852473 | J29: =D29*E21 -> 7147.28
B30: Totals | D30: =SUM(D26:D29) -> 3051948 | E30: =SUM(E26:E29) -> 3720000 | F30: =SUM(F26:F29) -> 327.74166 | G30: =SUM(G26:G29) -> 31000 | J30: =SUM(J26:J29) -> 34639.945
C33: Month | D33: Actual Sales monthly | E33: Target monthly | F33: Target achieved in % | G33: Prev Incentive | H33: Target | I33: Target Achieved | J33: New 5% NP
B34: Lalmatia | C34: Jan | D34: 556246 | E34: =33000*31 -> 1023000 | F34: =D34/E34*100 -> 54.373998 | G34: 800 | H34: =33000*31 -> 1023000 | I34: =D34/H34*100 -> 54.373998 | J34: =D34*C21 -> 2781.23
C35: Feb | D35: 581480 | E35: =33000*28 -> 924000 | F35: =D35/E35*100 -> 62.930736 | G35: 1800 | H35: =33000*28 -> 924000 | I35: =D35/H35*100 -> 62.930736 | J35: =D35*D21 -> 4361.1
C36: Mar | D36: 619527 | E36: =33000*31 -> 1023000 | F36: =D36/E36*100 -> 60.559824 | G36: 1600 | H36: =33000*31 -> 1023000 | I36: =D36/H36*100 -> 60.559824 | J36: =D36*D21 -> 4646.4525
C37: Apr | D37: 711082 | E37: =33000*30 -> 990000 | F37: =D37/E37*100 -> 71.826465 | G37: 3000 | H37: =33000*30 -> 990000 | I37: =D37/H37*100 -> 71.826465 | J37: =D37*E21 -> 7110.82
B38: Totals | D38: =SUM(D34:D37) -> 2468335 | E38: =SUM(E35:E37) -> 2937000 | F38: =SUM(F35:F37) -> 195.31702 | G38: =SUM(G35:G37) -> 6400 | J38: =SUM(J35:J37) -> 16118.372
A40: H | C40: Month | D40: Actual Sales monthly | E40: Target monthly | F40: Target achieved in % | G40: Prev Incentive | H40: Target | I40: Target Achieved | J40: New 5% NP
B41: Asian Tower | C41: Jan | D41: 1049100 | E41: =61000*31 -> 1891000 | F41: =D41/E41*100 -> 55.478583 | G41: 1000 | H41: =61000*31 -> 1891000 | I41: =D41/H41*100 -> 55.478583 | J41: =D41*C21 -> 5245.5
C42: Feb | D42: 930796 | E42: =61000*28 -> 1708000 | F42: =D42/E42*100 -> 54.496253 | H42: =61000*28 -> 1708000 | I42: =D42/H42*100 -> 54.496253 | J42: =D42*C21 -> 4653.98
C43: Mar | D43: 892677 | E43: =61000*31 -> 1891000 | F43: =D43/E43*100 -> 47.20661 | H43: =61000*31 -> 1891000 | I43: =D43/H43*100 -> 47.20661 | J43: =D43*C23 -> 0
C44: Apr | D44: 1735659 | E44: =61000*30 -> 1830000 | F44: =D44/E44*100 -> 94.844754 | G44: 13000 | H44: =61000*30 -> 1830000 | I44: =D44/H44*100 -> 94.844754 | J44: =D44*G21 -> 26034.885
B45: Totals | D45: =SUM(D41:D44) -> 4608232 | E45: =SUM(E42:E44) -> 5429000 | F45: =SUM(F42:F44) -> 196.54762 | G45: =SUM(G42:G44) -> 13000 | J45: =SUM(J42:J44) -> 30688.865
C47: Month | D47: Actual Sales monthly | E47: Target monthly | F47: Target achieved in % | G47: Prev Incentive | H47: Target | I47: Target Achieved | J47: New 5% NP
B48: Fakirapool | C48: Jan | D48: 194544 | E48: =27000*31 -> 837000 | F48: =D48/E48*100 -> 23.243011 | H48: =27000*31 -> 837000 | I48: =D48/H48*100 -> 23.243011
C49: Feb | D49: 240130 | E49: =27000*28 -> 756000 | F49: =D49/E49*100 -> 31.763228 | H49: =27000*28 -> 756000 | I49: =D49/H49*100 -> 31.763228
C50: Mar | D50: 282406 | E50: =27000*31 -> 837000 | F50: =D50/E50*100 -> 33.740263 | G50: 500 | H50: =27000*31 -> 837000 | I50: =D50/H50*100 -> 33.740263
C51: Apr | D51: 363565 | E51: =27000*30 -> 810000 | F51: =D51/E51*100 -> 44.884568 | H51: =27000*30 -> 810000 | I51: =D51/H51*100 -> 44.884568
B52: Totals | D52: =SUM(D48:D51) -> 1080645 | E52: =SUM(E48:E51) -> 3240000 | F52: =SUM(F49:F51) -> 110.38806 | G52: =SUM(G48:G51) -> 500 | J52: =SUM(J48:J51) -> 0
...

Sheet Breakeven- avg GP (2)
B1: ASSURANCE FARM OPC
B2: Proposed Break even Sales Statement
B3: Based on average GP
B5: Particulars | D5: Banani | E5: Nikunja (Asian Tower) | F5: Lalmatia | G5: Nurjahan Road | H5: Benaroshi Polli | I5: Fakirapul | J5: Mirpur DOHS | K5: Kazipara | L5: Mirpur-6 | M5: Banani DOHS | N5: Nikunja 01 | O5: Zakir Hossain Road
B6: Average monthly sale( based on last 6 month)
B7: Average daily sale( based on last 6 month)
B9: Break even Sales per Month | D9: =D26/(28)*100 -> 765466.17 | E9: =E26/(28)*100 -> 1445801.6 | F9: =F26/(28)*100 -> 1138966.2 | G9: =G26/(28)*100 -> 1082041.2 | H9: =H26/(28)*100 -> 1149819.7 | I9: =I26/(28)*100 -> 917530.46 | J9: =J26/(28)*100 -> 585265.23 | K9: =K26/(28)*100 -> 887609.03 | ... O9: =O26/(28)*100 -> 795228.08
B11: Gross Profit | D11: =D9*D13 -> 214330.53 | E11: =E9*E13 -> 404824.46 | F11: =F9*F13 -> 318910.53 | G11: =G9*G13 -> 302971.53 | H11: =H9*H13 -> 321949.53 | I11: =I9*I13 -> 256908.53 | J11: =J9*J13 -> 163874.26 | K11: =K9*K13 -> 248530.53 | ... O11: =O9*O13 -> 222663.86
B13: Considering Average GP % | D13: 0.28 | E13: 0.28 | F13: 0.28 | G13: 0.28 | H13: 0.28 | I13: 0.28 | J13: 0.28 | K13: 0.28 | L13: 0.28 | M13: 0.28 | N13: 0.28 | O13: 0.28
B15: Proposed Cost per Month
B16: Rent | D16: 40000 | E16: 138600 | F16: 105264 | G16: 75000 | H16: 115000 | I16: 65000 | J16: 35000 | K16: 60000 | L16: 45000 | M16: 60000 | N16: 35000 | O16: 40000
B17: Service Charge | D17: 0 | E17: 20000 | F17: 0 | G17: 0 | H17: 0 | I17: 0 | J17: 0 | K17: 0 | L17: 0 | M17: 0 | O17: 0
B18: Electricity | D18: 38000 | E18: 60000 | F18: 40000 | G18: 60000 | H18: 50000 | I18: 40000 | J18: 35000 | K18: 40000 | L18: 35000 | M18: 20000 | N18: 25000 | O18: 30000
B19: Wasa | D19: 0 | E19: 0 | F19: 3000 | G19: 0 | H19: 0 | I19: 2000 | J19: 0 | K19: 3700 | L19: 1100 | M19: 2000 | N19: 0 | O19: 2000
B20: AIT On Rent | D20: 0 | E20: 0 | F20: =F16*0.1 -> 10526.4 | G20: 0 | H20: 0 | I20: 0 | J20: 0 | K20: 3000 | L20: 0 | M20: 6000 | N20: 0 | O20: 0
B21: Vat on Rent | D21: 0 | E21: 9000 | F21: =F16*0.15 -> 15789.6 | G21: =G16*0.15 -> 11250 | H21: =25000*0.15 -> 3750 | I21: =30000*0.15 -> 4500 | J21: =J16*0.15 -> 5250 | K21: =30000*0.15 -> 4500 | L21: =L16*0.15 -> 6750 | M21: 0 | N21: =N16*0.15 -> 5250 | O21: =O16*0.15 -> 6000
B22: Salary & Allowances | D22: =D40*D46+D41*D47 -> 131330.53 | E22: =E40*D46+E41*D47 -> 169224.46 | F22: =F40*D46+F41*D47 -> 131330.53 | G22: =G40*D46+G41*D47 -> 131330.53 | H22: =H40*D46+H41*D47 -> 131330.53 | I22: =I40*D46+I41*D47 -> 131330.53 | J22: =J40*D46+J41*D47+(5400+3600*2) -> 78265.264 | K22: =K40*D46+K41*D47 -> 131330.53 | L22: =L40*D46+L41*D47 -> 84612.23 | M22: =M40*D46+M41*D47 -> 131330.53 | N22: =N40*D46+N41*D47+(5400+3600*2) -> 78265.264 | O22: =D46*2+D47*4 -> 131330.53
B23: Maintenance | D23: 5000 | E23: 8000 | F23: 6000 | G23: 8000 | H23: 8000 | I23: 5000 | J23: 5000 | K23: 6000 | L23: 5000 | M23: 5000 | N23: 5000 | O23: 5000
B24: Cost of Fund | F24: 7000 | G24: 17391 | H24: 13869 | I24: 9078 | J24: 5359 | K24: 0 | L24: 7131 | M24: 4375 | N24: 5381 | O24: =(1000000*0.1*3)/36 -> 8333.3333
B25: Depreciation (not considered) | D25: 0 | E25: 0
B26: Total Proposed Cost | D26: =SUM(D16:D25) -> 214330.53 | E26: =SUM(E16:E25) -> 404824.46 | F26: =SUM(F16:F25) -> 318910.53 | G26: =SUM(G16:G25) -> 302971.53 | H26: =SUM(H16:H25) -> 321949.53 | I26: =SUM(I16:I25) -> 256908.53 | J26: =SUM(J16:J25) -> 163874.26 | K26: =SUM(K16:K25) -> 248530.53 | ... N26: =SUM(N16:N25) -> 153896.26 | O26: =SUM(O16:O24) -> 222663.86
B28: Profit/ (Loss) | D28: =D11-D26 -> 0 | E28: =E11-E26 -> 0 | F28: =F11-F26 -> 0 | G28: =G11-G26 -> 0 | H28: =H11-H26 -> 0 | I28: =I11-I26 -> 0 | J28: =J11-J26 -> 0 | K28: =K11-K26 -> 0 | ... M28: =M11-M26 -> 0
B32: Break even Sales per Day | D32: =D9/30 -> 25515.539 | E32: =E9/30 -> 48193.388 | F32: =F9/30 -> 37965.539 | G32: =G9/30 -> 36068.039 | H32: =H9/30 -> 38327.325 | I32: =I9/30 -> 30584.349 | J32: =J9/30 -> 19508.841 | K32: =K9/30 -> 29586.968 | ... O32: =O9/30 -> 26507.603
B34: Present Sales target/day | D34: 31000 | E34: 61000 | F34: 33000 | G34: 40000 | H34: 44000 | I34: 27000 | J34: 0 | K34: 0 | L34: 0 | M34: 30000 | N34: 0
B36: Proposed Sales target/day | D36: 35000 | E36: 62000 | F36: 49000 | G36: 42000 | H36: 45000 | I36: 31000 | J36: 23000 | K36: 38000 | L36: 29000 | M36: 33000 | N36: 21000 | O36: 24000
B38: Shift | D38: 2 | E38: 2 | F38: 2 | G38: 2 | H38: 2 | I38: 2 | J38: 1 | K38: 2 | L38: 2 | M38: 2 | N38: 1 | O38: 2
B40: Incharge/Barista | D40: 2 | E40: 2 | F40: 2 | G40: 2 | H40: 2 | I40: 2 | J40: 1 | K40: 2 | L40: 1 | M40: 2 | N40: 1 | O40: 2
B41: Surver/Outlet Asstt | D41: 4 | E41: 6 | F41: 4 | G41: 4 | H41: 4 | I41: 4 | J41: 2 | K41: 4 | L41: 3 | M41: 4 | N41: 2 | O41: 4
B45: Average Salary & Allowances:
B46: Incharge/Barista | D46: 27771.333
B47: Surver/Outlet Asstt | D47: 18946.966
B49: Required daily Sales
B51: Name of Outlet | D51: Average Cost | F51: Breakeven Sales/day (avg. GP-28%) | G51: Sales amount against Net Profit | I51: Sales Target / day
D52: Per Month | E52: Per Day | G52: 0.05 | H52: 0.1
B53: Banani | D53: =M70 -> 214330.53 | E53: =D53/30 -> 7144.351 | F53: =E53/28*100 -> 25515.539 | G53: =E53/23*100 -> 31062.395 | H53: =E53/18*100 -> 39690.839 | I53: 31000
B54: Nikunja (Asian Tower) | D54: =M71 -> 404824.46 | E54: =D54/30 -> 13494.149 | F54: =E54/28*100 -> 48193.388 | G54: =E54/23*100 -> 58670.212 | H54: =E54/18*100 -> 74967.493 | I54: 59000
B55: Lalmatia | D55: =M72 -> 318910.53 | E55: =D55/30 -> 10630.351 | F55: =E55/28*100 -> 37965.539 | G55: =E55/23*100 -> 46218.917 | H55: =E55/18*100 -> 59057.505 | I55: 46000
B56: Nurjahan Road | D56: =M73 -> 302971.53 | E56: =D56/30 -> 10099.051 | F56: =E56/28*100 -> 36068.039 | G56: =E56/23*100 -> 43908.917 | H56: =E56/18*100 -> 56105.839 | I56: 44000
B57: Benaroshi Polli | D57: =M74 -> 321949.53 | E57: =D57/30 -> 10731.651 | F57: =E57/28*100 -> 38327.325 | G57: =E57/23*100 -> 46659.352 | H57: =E57/18*100 -> 59620.283 | I57: 47000
B58: Fakirapul | D58: =M75 -> 256908.53 | E58: =D58/30 -> 8563.6176 | F58: =E58/28*100 -> 30584.349 | G58: =E58/23*100 -> 37233.12 | H58: =E58/18*100 -> 47575.653 | I58: 37000
...

Sheet Farm-26
B2: Participant list
B3: SL | C3: Name | D3: ID | E3: Designation | F3: D.O.J | G3: Phone | H3: Salary Amount | I3: Allowances | J3: Total Amount
B4: 1 | C4: Jahidul Islam | D4: 700093 | E4: Incharge cum Barista | F4: 25.06.25/05.02.26 | G4: 1910210582 | H4: 27000 | I4: 3255 | J4: =H4+I4 -> 30255
B5: 2 | C5: Md. Sahadat Hossain | D5: 700075 | E5: Incharge cum Barista | F5: 14.12.25 | G5: 1300542466 | H5: 23000 | I5: 11947 | J5: =H5+I5 -> 34947
B6: 3 | C6: Rakibul Islam | D6: 700065 | E6: Sales Executive | F6: 15.11.25 | G6: 1540695291 | H6: 13000 | I6: 6220 | J6: =H6+I6 -> 19220
B7: 4 | C7: Anita Mrong | D7: 700056 | E7: Outlet Asstt | F7: 05.11.25 | G7: 1936276818 | H7: 13000 | I7: 6220 | J7: =H7+I7 -> 19220
B8: 5 | C8: Laskmi | D8: 700057 | E8: Outlet Asstt. | F8: 08.11.25 | G8: 1946278945 | H8: 13000 | I8: 3720 | J8: =H8+I8 -> 16720
B9: 6 | C9: Redwan Masud | D9: 700044 | E9: In- Charge | F9: 01.07.25 | G9: 1730373458 | H9: 21000 | I9: 11590 | J9: =H9+I9 -> 32590
B10: 7 | C10: Md.Isbat Zaman Tawsif | D10: 700082 | E10: Barista | F10: 01.01.26 | G10: 1751577561 | H10: 23000 | I10: 5619 | J10: =H10+I10 -> 28619
B11: 8 | C11: Md. Nazmul Hossain Nahid | D11: 700041 | E11: Sales Executive | F11: 23.06.25 | G11: 1673580076 | H11: 12000 | I11: 3100 | J11: =H11+I11 -> 15100
B12: 9 | C12: Md. Shuvon Ahmed | D12: 700077 | E12: Sales Executive | F12: 20.12.25 | G12: 1325438591 | H12: 15000 | I12: 8694 | J12: =H12+I12 -> 23694
B13: 10 | C13: Md. Ronju Ahmed | D13: 700042 | E13: In- Charge | F13: 25.06.25 | G13: 1730373613 | H13: 24000 | I13: 10899 | J13: =H13+I13 -> 34899
B14: 11 | C14: Razib Khan | D14: 700033 | E14: Jr. Barista | F14: 09.04.25 | G14: 1730088540 | H14: 20000 | I14: 3410 | J14: =H14+I14 -> 23410
B15: 12 | C15: Somapty Nokrek | D15: 700087 | E15: Outlet Assistant | F15: 24.01.26 | G15: 1327789763 | H15: 13000 | I15: 4300 | J15: =H15+I15 -> 17300
... B46: 43 | C46: Babilon Chakma | D46: 700098 | E46: Sales Executive | F46: 28.02.26 | G46: 1946075439 | H46: 16000 | I46: 155 | J46: =H46+I46 -> 16155
B47: 44 | C47: Sano Mong Marma | D47: 700099 | E47: Outlet In Charge | F47: 01.03.26 | G47: 1402043017 | H47: 20000 | J47: =H47+I47 -> 20000
B48: 45 | C48: Bishagit Baidya Raj | D48: 700047 | E48: Bakery Chef | H48: 40000 | I48: 3410 | J48: =H48+I48 -> 43410
B49: 46 | C49: Xavier Gomes | D49: 700052 | E49: Kitchen Helper | H49: 13000 | I49: 3100 | J49: =H49+I49 -> 16100
B50: 47 | C50: Mohammad Hasan Ahmmod | D50: 700061 | E50: Commis 2 | H50: 22000 | I50: 3410 | J50: =H50+I50 -> 25410
B51: 48 | C51: Md. Reyad Akhon | D51: 700062 | E51: Commis 2 | H51: 18000 | I51: 3565 | J51: =H51+I51 -> 21565
B52: 49 | C52: Raeduggaman | D52: 700072 | E52: Assistant Chef | H52: 28000 | I52: 3565 | J52: =H52+I52 -> 31565
H56: =SUM(H4:H52) -> 842000 | I56: =SUM(I4:I52) -> 245547 | J56: =SUM(J4:J52) -> 1087547
J57: =SUBTOTAL(9,J6:J52) -> 1022345
B79: Incharge
B81: 1 | C81: Jahidul Islam | D81: 700093 | E81: Incharge cum Barista | F81: 25.06.25/05.02.26 | G81: 1910210582 | H81: 27000 | I81: 6243 | J81: =H81+I81 -> 33243
B82: 2 | C82: Md. Sahadat Hossain | D82: 700075 | E82: Incharge cum Barista | F82: 14.12.25 | G82: 1300542466 | H82: 23000 | I82: 6243 | J82: =H82+I82 -> 29243
B83: 3 | C83: Redwan Masud | D83: 700044 | E83: In- Charge | F83: 01.07.25 | G83: 1730373458 | H83: 21000 | I83: 6243 | J83: =H83+I83 -> 27243
B84: 4 | C84: Md.Isbat Zaman Tawsif | D84: 700082 | E84: Barista | F84: 01.01.26 | G84: 1751577561 | H84: 23000 | I84: 6243 | J84: =H84+I84 -> 29243
B85: 5 | C85: Md. Ronju Ahmed | D85: 700042 | E85: In- Charge | F85: 25.06.25 | G85: 1730373613 | H85: 24000 | I85: 6243 | J85: =H85+I85 -> 30243
B86: 6 | C86: MD Rihad | D86: 700059 | E86: Barista | F86: 12.11.25 | G86: 1757733370 | H86: 18000 | I86: 6243 | J86: =H86+I86 -> 24243
B87: 7 | C87: Ferdous Ahmed | D87: 700039 | E87: Barista | F87: 14.06.25 | G87: 1712308009 | H87: 22000 | I87: 6243 | J87: =H87+I87 -> 28243
B88: 8 | C88: Rakibul Islam | D88: 700002 | E88: In- Charge | F88: 20.12.22 | G88: 1730373479 | H88: 22000 | I88: 6243 | J88: =H88+I88 -> 28243
B89: 9 | C89: Md.Mazharul Islam Rakib | D89: 700088 | E89: Barista | F89: 26.01.26 | G89: 1705813113 | H89: 18000 | I89: 6243 | J89: =H89+I89 -> 24243
B90: 10 | C90: Refakur Reza | D90: 700085 | E90: Barista | F90: 20.01.26 | G90: 1400457241 | H90: 18000 | I90: 6243 | J90: =H90+I90 -> 24243
B91: 11 | C91: Shamim Sheikh | D91: 700081 | E91: Barista | F91: 01.01.26 | G91: 1957719741 | H91: 23000 | I91: 6243 | J91: =H91+I91 -> 29243
B92: 12 | C92: Jewel Rana | D92: 700089 | E92: Barista | F92: 01.02.26 | G92: 1741986291 | H92: 18000 | I92: 6243 | J92: =H92+I92 -> 24243
... B94: 14 | C94: Sano Mong Marma | D94: 700099 | E94: Outlet In Charge | F94: 01.03.26 | G94: 1402043017 | H94: 20000 | I94: 6243 | J94: =H94+I94 -> 26243
B95: 15 | C95: Taiyabur Rahman Taiyab | D95: 700132 | E95: Barista | F95: 26.04.26 | H95: 20500 | I95: 6243 | J95: =H95+I95 -> 26743
B96: 16 | C96: Md. Emon Hossain | D96: 700012 | E96: Barista | F96: 11.04.26 | H96: 18000 | I96: 6243 | J96: =H96+I96 -> 24243
B97: 17 | C97: Md. Ratul Talukder | D97: 700110 | E97: Incharge cum Barista | F97: 01.04.26 | H97: 20000 | I97: 6243 | J97: =H97+I97 -> 26243
...
